<mujoco model="igor">
    <option timestep="0.002" gravity="0 0 -9.81" />
    <compiler angle="radian" assetdir="assets"/>
    <size njmax="500" nconmax="500" />

    <default>
    <default class="visual">
      <geom type="mesh" contype="0" conaffinity="0" group="2"/>
    </default>
    <default class="collision">
        <geom contype="1" conaffinity="1" group="3"/>
        </default>
    </default>

    <asset>
        <texture builtin="gradient" height="100" rgb1="1 1 1" rgb2="0 0 0" type="skybox" width="100"/>
        <texture builtin="flat" height="1278" mark="cross" markrgb="1 1 1" name="texgeom" random="0.01" rgb1="0.8 0.6 0.4" rgb2="0.8 0.6 0.4" type="cube" width="127"/>
        <texture builtin="checker" height="100" name="texplane" rgb1="0.68 1 0.83" rgb2="0 0.75 1" type="2d" width="100"/>
        <material name="MatPlane" reflectance="0.0" shininess="10" specular="1" texrepeat="60 60" texture="texplane"/>

        <material name="geom" texture="texgeom" texuniform="true"/>
        <hfield name='mytilted' file='ground_wavy.png' nrow='0' ncol='0' size='30 30 0.3 0.01' />

        <mesh file="wheel.STL" scale="0.001 0.001 0.001"/>
        <mesh file="IgorWheel.STL" scale="0.001 0.001 0.001"/>
        <mesh file="X8-Export.STL" scale="0.001 0.001 0.001"/>
        <mesh file="lowerLeg.STL" scale="0.001 0.001 0.001"/>
        <mesh file="upperLeg.STL" scale="0.001 0.001 0.001"/>

        <!-- <texture filefront="logo_e_n.png" name="logo" rgb1="0.243 0.082 0.525" /> -->
        <!-- <material name="logo" texture="logo" rgba="0.3 0.3 0.3 1" reflectance="0" shininess="500" specular="0"/> -->
    </asset>

    <worldbody>
        <!-- <geom conaffinity="1" condim="3" material="MatPlane" name="floor" pos="0 0 0" rgba="255 255 255 1" size="40 40 40" type="plane"/> -->
        <!-- <geom conaffinity="1"  friction="3 0.005 0.0001" hfield="mytilted" material="MatPlane" name="floor" pos="0 0 0" rgba="255 255 255 1" type="hfield"/> -->

        <body name="torso" pos="0 0 0.9">
            <geom size="0.045 0.1525 0.109" type="box" rgba="0.3 0.3 0.3 1" />
            <geom mass="0" size="0.045 0.1525 0.109" type="box" rgba="0.3 0.3 0.3 1" class="visual"/>
            <!-- <geom mass="0" quat="0.5 0.5 0.5 0.5" size="0.1526 0.110 0.046" type="box" rgba="0.3 0.3 0.3 1" material="logo"/> -->
            <!-- <geom size="0.055 0.0225 0.0365" pos="0 0.175 -0.06" type="box" rgba="0.3 0.3 0.3 1" material="logo" />
            <geom size="0.055 0.0225 0.0365" pos="0 -0.175 -0.06" type="box" rgba="0.3 0.3 0.3 1" material="logo" /> -->
            <!-- <joint armature="0" damping="0" axis="1 0 0" limited="false" stiffness="0" name="rootx" pos="0 0 0" type="slide"/>
            <joint armature="0" damping="0" axis="0 0 1" limited="false" stiffness="0" name="rootz" pos="0 0 0" type="slide"/>
            <joint armature="0" damping="0" axis="0 1 0" limited="false" stiffness="0" name="rooty" pos="0 0 0" type="hinge"/> -->
            <geom pos="0.035 0.155 -0.1" quat="4.32963729e-17 4.32963729e-17 7.07106781e-01 7.07106781e-01" type="mesh" mesh="X8-Export" rgba="1 0 0 1" contype="0" conaffinity="0"/>
            <geom pos="0.035 -0.155 -0.025" quat="4.32963729e-17 -4.32963729e-17 -7.07106781e-01  7.07106781e-01" type="mesh" mesh="X8-Export" rgba="1 0 0 1" contype="0" conaffinity="0"/>
            <freejoint name="free"/>
            <body name="L_upperleg" pos="0 0.213375 -0.06">

                <inertial pos="0 -0.0259596 -0.309843" quat="0.70542 -0.0488131 0.0488131 0.70542" mass="0.68" diaginertia="0.00899163 0.00867248 0.000646855" />
                <joint name="L_hfe_joint" pos="0 0 0" axis="0 1 0" limited="true" range="-6.28318 6.28318" damping="10" />

                <geom size="0.015875 0.175" pos="0 0 -0.175" type="cylinder" rgba="1 1 1 0" />
                <geom pos="0.03 -0.045 0.025" quat="0.5 -0.5 0.5 0.5" type="mesh" mesh="upperLeg" rgba="0.3 0.3 0.3 1" contype="0" conaffinity="0"/>

                <geom size="0.055 0.0225 0.0365" pos="0 -0.038375 -0.374333" type="box" rgba="1 0 0 0" />
                <geom pos="-0.035 -0.014 -0.41" quat="0.707 0.707 0 0" type="mesh" mesh="X8-Export" rgba="1 0 0 1" contype="0" conaffinity="0"/>

                <body name="L_lowerleg" pos="0 -0.07675 -0.374333">
                    <inertial pos="0 0.0287152 -0.274897" quat="0.70457 0.0598424 -0.0598424 0.70457" mass="0.66" diaginertia="0.0068334 0.00651392 0.000642521" />
                    <joint name="L_kfe_joint" pos="0 0 0" axis="0 1 0" limited="true" range="-6.28318 6.28318" damping="10" />

                    <geom size="0.015875 0.15" pos="0 0 -0.15" type="cylinder" rgba="1 1 1 0" />
                    <geom pos="0.045 0.035 -0.38" type="mesh" quat="0.5 0.5 -0.5 0.5" mesh="lowerLeg" rgba="0.3 0.3 0.3 1" contype="0" conaffinity="0"/>

                    <geom size="0.055 0.0225 0.0365" pos="0 0.0412 -0.3292" type="box" rgba="1 0 0 0" />
                    <geom pos="-0.035 0.02 -0.292" quat="0.707 -0.707 0 0" type="mesh" mesh="X8-Export" rgba="1 0 0 1" contype="0" conaffinity="0"/>

                    <body name="L_wheel" pos="0 0.0787 -0.3292">
                        <inertial pos="0 0 0" quat="0.707107 0 0 0.707107" mass="0.35" diaginertia="0.001806 0.000929 0.000929" />
                        <joint name="L_wheel_joint" pos="0 0 0" axis="0 1 0" damping="0.25" frictionloss="0.0011" />

                        <geom size="0.1016 0.015" quat="0.707107 0.707106 0 0" type="cylinder" rgba="1 1 1 0" />
                        <geom pos ="-0.1016 -0.1016 -0.1016 " type="mesh" mesh="wheel" rgba="0.3 0.3 0.3 1" contype="0" conaffinity="0" />

                        <site name="L_sensor" size="0.1016 0.015" quat="0.707107 0.707106 0 0" type="cylinder" rgba="1 0 0 0" />
                    </body>
                </body>
            </body>
            <body name="R_upperleg" pos="0 -0.213375 -0.06">
                <inertial pos="0 0.0259596 -0.309843" quat="0.70542 0.0488131 -0.0488131 0.70542" mass="0.68" diaginertia="0.00899163 0.00867248 0.000646855" />
                <joint name="R_hfe_joint" pos="0 0 0" axis="0 1 0" limited="true" range="-6.28318 6.28318" damping="10" />

                <geom size="0.015875 0.175" pos="0 0 -0.175" type="cylinder" rgba="1 1 1 0" />
                <geom pos="-0.031 0.045 0.025" type="mesh" quat="-0.5 -0.5 -0.5 0.5" mesh="upperLeg" rgba="0.3 0.3 0.3 1" contype="0" conaffinity="0"/>

                <geom size="0.055 0.0225 0.0365" pos="0 0.038375 -0.374333" type="box" rgba="1 0 0 0" />
                <geom pos="-0.035 0.014 -0.337" quat="0.707 -0.707 0 0" type="mesh" mesh="X8-Export" rgba="1 0 0 1" contype="0" conaffinity="0"/>

                <body name="R_lowerleg" pos="0 0.07675 -0.374333">
                    <inertial pos="0 -0.0287152 -0.274897" quat="0.70457 -0.0598424 0.0598424 0.70457" mass="0.66" diaginertia="0.0068334 0.00651392 0.000642521" />
                    <joint name="R_kfe_joint" pos="0 0 0" axis="0 1 0" limited="true" range="-6.28318 6.28318" damping="10" />

                    <geom size="0.015875 0.15" pos="0 0 -0.15" type="cylinder" rgba="1 1 1 0" />
                    <geom pos="-0.04 -0.035 -0.38" type="mesh" quat="-0.5 0.5 0.5 0.5" mesh="lowerLeg" rgba="0.3 0.3 0.3 1" contype="0" conaffinity="0"/>

                    <geom size="0.055 0.0225 0.0365" pos="0 -0.0412 -0.3292" type="box" rgba="1 0 0 0" />
                    <geom pos="-0.035 -0.02 -0.365" type="mesh" quat="0.707 0.707 0 0" mesh="X8-Export" rgba="1 0 0 1" contype="0" conaffinity="0"/>

                    <body name="R_wheel" pos="0 -0.0787 -0.3292">
                        <inertial pos="0 0 0" quat="0.707107 0 0 0.707107" mass="0.35" diaginertia="0.001806 0.000929 0.000929" />
                        <joint name="R_wheel_joint" pos="0 0 0" axis="0 1 0" damping="0.25" frictionloss="0.0011" />

                        <geom size="0.1016 0.015" quat="0.707107 0.707106 0 0" type="cylinder" rgba="1 1 1 0" />
                        <geom pos="-0.1016 -0.1016 -0.1016" type="mesh" mesh="wheel" rgba="0.3 0.3 0.3 1" contype="0" conaffinity="0"/>

                        <site name="R_sensor" size="0.1016 0.015" quat="0.707107 0.707106 0 0" type="cylinder" rgba="1 0 0 0" />
                    </body>
                </body>
            </body>
        </body>
    </worldbody>

    <actuator>
        <!-- <motor joint='L_wheel_joint' name='l_wheel_joint' gear="1"/>
        <motor joint='R_wheel_joint' name='r_wheel_joint' gear="1"/>
        <motor joint='L_kfe_joint' name='L_knee_joint' gear="1" />
        <motor joint='R_kfe_joint' name='R_knee_joint' gear="1" />
        <motor joint='L_hfe_joint' name='L_hip_joint' gear="1" />
        <motor joint='R_hfe_joint' name='R_hip_joint' gear="1" /> -->
        <general joint='L_wheel_joint' name='l_wheel_joint' forcerange="-3 3" biastype="affine" gainprm="50 0 0" biasprm="0 -50 -0.5"/>
        <general joint='R_wheel_joint' name='r_wheel_joint' forcerange="-3 3" biastype="affine" gainprm="50 0 0" biasprm="0 -50 -0.5"/>
        <general joint='L_kfe_joint' name='L_knee_joint' forcerange="-16 16" biastype="affine" gainprm="50 0 0" biasprm="0 -50 -0.5"/>
        <general joint='R_kfe_joint' name='R_knee_joint' forcerange="-16 16" biastype="affine" gainprm="50 0 0" biasprm="0 -50 -0.5"/>
        <general joint='L_hfe_joint' name='L_hip_joint' forcerange="-8 8" biastype="affine" gainprm="50 0 0" biasprm="0 -50 -0.5"/>
        <general joint='R_hfe_joint' name='R_hip_joint' forcerange="-8 8" biastype="affine" gainprm="50 0 0" biasprm="0 -50 -0.5"/>
    </actuator>

    <sensor>
        <touch name="L_touch" site="L_sensor"/>
        <touch name="R_touch" site="R_sensor"/>
    </sensor>
</mujoco>
